Workbook

Sheet 물질정보
A1: 내부식별자 | B1: CAS | C1: 물질명 | D1: 분자식 | E1: 분자량 | F1: SMILES
A2: A-1 | B2: - | C2: 9-(9H-Carbazol-9-yl)-7H-benzo[c]carbazole | D2: C28H18N2 | E2: 382.5 g/mol | F2: C1=CC=C2C(=C1)C=CC3=C2C4=C(N3)C=C(C=C4)N5C6=CC=CC=C6C7=CC=CC=C75 | G2: c1ccc4c(c1)ccc3[nH]c2cc(ccc2c34)n6c7ccccc7(c5ccccc56)
A3: A-2 | B3: 205-25-4 | C3: 7H-Benzo[c]carbazole | D3: C16H11N | E3: 217.26 g/mol | F3: C1=CC=C2C(=C1)C=CC3=C2C4=CC=CC=C4N3
A4: B-1 | B4: 97-63-2 | C4: ethyl methacrylate | D4: C6H10O2 | E4: 114.14 g/mol | F4: CCOC(=O)C(=C)C
A5: B-2 | B5: 868-77-9 | C5: 2-hydroxyethyl methacrylate | D5: C6H10O3 | E5: 130.139 g/mol | F5: CC(=C)C(=O)OCCO
A6: B-3 | B6: 97-88-1 | C6: butyl methacrylate | D6: C8H14O2 | E6: 142.2 g/mol | F6: CCCCOC(=O)C(=C)C
A7: B-4 | B7: 997-46-6 | C7: 4-hydroxybutyl methacrylate | D7: C8H14O3 | E7: 158.19 g/mol | F7: CC(=C)C(=O)OCCCCO
A8: B-5 | B8: 140-88-5 | C8: ethyl acrylate | D8: C5H8O2 | E8: 100.12 g/mol | F8: CCOC(=O)C=C
A9: B-6 | B9: 818-61-1 | C9: 2-hydroxyethyl acrylate | D9: C5H8O3 | E9: 116.11 g/mol | F9: C=CC(=O)OCCO
A10: B-7 | B10: 141-32-2 | C10: butyl acrylate | D10: C7H12O2 | E10: 128.169 g/mol | F10: CCCCOC(=O)C=C
A11: B-8 | B11: 2478-10-6 | C11: 4-hydroxybutyl acrylate | D11: C7H12O3 | E11: 144.17 g/mol | F11: C=CC(=O)OCCCCO
A12: B-9 | B12: 2499-95-8 | C12: hexyl acrylate | D12: C9H16O2 | E12: 156.22 g/mol | F12: CCCCCCOC(=O)C=C
A13: B-10 | B13: 10095-14-4 | C13: 6-hydroxybutyl acrylate | D13: C9H16O3 | E13: 172.22 g/mol | F13: C=CC(=O)OCCCCCCO

Sheet 유해성정보
A1: 우선순위 | B1: 내부식별자 | C1: CAS | D1: 물질명 | E1: 분자식 | F1: 분자량 | G1: SMILES | H1: 대분류 | I1: 유해성항목 | J1: Endpoint | K1: Result | L1: 단위 | M1: 시험종 | N1: Strain | O1: 성별 | P1: Duration | Q1: Duration_unit | R1: 결과도출방법 | S1: 시험지침 | T1: Domain status | U1: 모델 종류 및 버전 | V1: 출처 | W1: 시험종(표준) | X1: Duration(표준) | Y1: Endpoint(표준)
B2: B-3 | C2: =VLOOKUP(B2,[1]물질정보!B:C,2,0) -> 97-88-1 | D2: =VLOOKUP(B2,[1]물질정보!B:D,3,0) -> butyl methacrylate | E2: =VLOOKUP(B2,[1]물질정보!B:E,4,0) -> C8H14O2 | F2: =VLOOKUP(B2,[1]물질정보!B:F,5,0) -> 142.2 g/mol | G2: =VLOOKUP(B2,[1]물질정보!B:G,6,0) -> CCCCOC(=O)C(=C)C | H2: 환경 | I2: 담수조류생장저해 | J2: EC50 | K2: - | L2: log(mmol/L) | M2: - | N2: - | O2: - | P2: 96 | Q2: h | R2: QSAR | S2: - | T2: Not applicable | U2: ECOSAR: GREEN ALGAE 96 h EC50 Growth (v1.11) | V2: QSAR Toolbox v.4.8 | W2: Green Algae | X2: 96 h | Y2: EC50
B3: B-3 | C3: =VLOOKUP(B3,[1]물질정보!B:C,2,0) -> 97-88-1 | D3: =VLOOKUP(B3,[1]물질정보!B:D,3,0) -> butyl methacrylate | E3: =VLOOKUP(B3,[1]물질정보!B:E,4,0) -> C8H14O2 | F3: =VLOOKUP(B3,[1]물질정보!B:F,5,0) -> 142.2 g/mol | G3: =VLOOKUP(B3,[1]물질정보!B:G,6,0) -> CCCCOC(=O)C(=C)C | H3: 환경 | I3: 담수조류생장저해 | J3: EC50 | K3: - | L3: log(mmol/L) | M3: - | N3: - | O3: - | P3: 96 | Q3: h | R3: QSAR | S3: - | T3: Not applicable | U3: ECOSAR: ALGAE 96 h EC50 Growth (v1.11) | V3: QSAR Toolbox v.4.8 | W3: Green Algae | X3: 96 h | Y3: EC50
B4: B-3 | C4: =VLOOKUP(B4,[1]물질정보!B:C,2,0) -> 97-88-1 | D4: =VLOOKUP(B4,[1]물질정보!B:D,3,0) -> butyl methacrylate | E4: =VLOOKUP(B4,[1]물질정보!B:E,4,0) -> C8H14O2 | F4: =VLOOKUP(B4,[1]물질정보!B:F,5,0) -> 142.2 g/mol | G4: =VLOOKUP(B4,[1]물질정보!B:G,6,0) -> CCCCOC(=O)C(=C)C | H4: 환경 | I4: 담수조류생장저해 | J4: EC50 | K4: 23.59368 | L4: mg/L | M4: - | N4: - | O4: - | P4: 72 | Q4: h | R4: QSAR | S4: - | T4: In domain | U4: Pseudokirchneriella subcapitata 72h EC50 - Danish QSAR DB battery model (v1.0) | V4: QSAR Toolbox v.4.8 | W4: P. subcapitata | X4: 72 h | Y4: EC50
B5: B-3 | C5: =VLOOKUP(B5,[1]물질정보!B:C,2,0) -> 97-88-1 | D5: =VLOOKUP(B5,[1]물질정보!B:D,3,0) -> butyl methacrylate | E5: =VLOOKUP(B5,[1]물질정보!B:E,4,0) -> C8H14O2 | F5: =VLOOKUP(B5,[1]물질정보!B:F,5,0) -> 142.2 g/mol | G5: =VLOOKUP(B5,[1]물질정보!B:G,6,0) -> CCCCOC(=O)C(=C)C | H5: 환경 | I5: 담수조류생장저해 | J5: EC50 | K5: 23.59368 | L5: mg/L | M5: - | N5: - | O5: - | P5: 72 | Q5: h | R5: QSAR | S5: - | T5: In domain | U5: Pseudokirchneriella subcapitata 72h EC50 - Danish QSAR DB battery model (v1.0) | V5: QSAR Toolbox v.4.8 | W5: P. subcapitata | X5: 72 h | Y5: EC50
B6: B-3 | C6: =VLOOKUP(B6,[1]물질정보!B:C,2,0) -> 97-88-1 | D6: =VLOOKUP(B6,[1]물질정보!B:D,3,0) -> butyl methacrylate | E6: =VLOOKUP(B6,[1]물질정보!B:E,4,0) -> C8H14O2 | F6: =VLOOKUP(B6,[1]물질정보!B:F,5,0) -> 142.2 g/mol | G6: =VLOOKUP(B6,[1]물질정보!B:G,6,0) -> CCCCOC(=O)C(=C)C | H6: 환경 | I6: 담수조류생장저해 | J6: EC50 | K6: 23.59368 | L6: mg/L | M6: - | N6: - | O6: - | P6: 72 | Q6: h | R6: QSAR | S6: - | T6: In domain | U6: Pseudokirchneriella subcapitata 72h EC50 - Danish QSAR DB battery model (v1.0) | V6: QSAR Toolbox v.4.8 | W6: P. subcapitata | X6: 72 h | Y6: EC50
B7: B-3 | C7: =VLOOKUP(B7,[1]물질정보!B:C,2,0) -> 97-88-1 | D7: =VLOOKUP(B7,[1]물질정보!B:D,3,0) -> butyl methacrylate | E7: =VLOOKUP(B7,[1]물질정보!B:E,4,0) -> C8H14O2 | F7: =VLOOKUP(B7,[1]물질정보!B:F,5,0) -> 142.2 g/mol | G7: =VLOOKUP(B7,[1]물질정보!B:G,6,0) -> CCCCOC(=O)C(=C)C | H7: 환경 | I7: 물벼룩급성독성 | J7: EC50 | K7: 34.42406 | L7: mg/L | M7: - | N7: - | O7: - | P7: 48 | Q7: h | R7: QSAR | S7: - | T7: In domain | U7: Daphnia magna 48h EC50 - Danish QSAR DB battery model (v1.0) | V7: QSAR Toolbox v.4.8 | W7: Daphnia magna | X7: 48 h | Y7: EC50
B8: B-3 | C8: =VLOOKUP(B8,[1]물질정보!B:C,2,0) -> 97-88-1 | D8: =VLOOKUP(B8,[1]물질정보!B:D,3,0) -> butyl methacrylate | E8: =VLOOKUP(B8,[1]물질정보!B:E,4,0) -> C8H14O2 | F8: =VLOOKUP(B8,[1]물질정보!B:F,5,0) -> 142.2 g/mol | G8: =VLOOKUP(B8,[1]물질정보!B:G,6,0) -> CCCCOC(=O)C(=C)C | H8: 환경 | I8: 물벼룩급성독성 | J8: EC50 | K8: 34.42406 | L8: mg/L | M8: - | N8: - | O8: - | P8: 48 | Q8: h | R8: QSAR | S8: - | T8: In domain | U8: Daphnia magna 48h EC50 - Danish QSAR DB battery model (v1.0) | V8: QSAR Toolbox v.4.8 | W8: Daphnia magna | X8: 48 h | Y8: EC50
B9: B-3 | C9: =VLOOKUP(B9,[1]물질정보!B:C,2,0) -> 97-88-1 | D9: =VLOOKUP(B9,[1]물질정보!B:D,3,0) -> butyl methacrylate | E9: =VLOOKUP(B9,[1]물질정보!B:E,4,0) -> C8H14O2 | F9: =VLOOKUP(B9,[1]물질정보!B:F,5,0) -> 142.2 g/mol | G9: =VLOOKUP(B9,[1]물질정보!B:G,6,0) -> CCCCOC(=O)C(=C)C | H9: 환경 | I9: 물벼룩급성독성 | J9: EC50 | K9: 34.42406 | L9: mg/L | M9: - | N9: - | O9: - | P9: 48 | Q9: h | R9: QSAR | S9: - | T9: In domain | U9: Daphnia magna 48h EC50 - Danish QSAR DB battery model (v1.0) | V9: QSAR Toolbox v.4.8 | W9: Daphnia magna | X9: 48 h | Y9: EC50
B10: B-3 | C10: =VLOOKUP(B10,[1]물질정보!B:C,2,0) -> 97-88-1 | D10: =VLOOKUP(B10,[1]물질정보!B:D,3,0) -> butyl methacrylate | E10: =VLOOKUP(B10,[1]물질정보!B:E,4,0) -> C8H14O2 | F10: =VLOOKUP(B10,[1]물질정보!B:F,5,0) -> 142.2 g/mol | G10: =VLOOKUP(B10,[1]물질정보!B:G,6,0) -> CCCCOC(=O)C(=C)C | H10: 환경 | I10: 물벼룩급성독성 | J10: LC50 | K10: 6.1943902 | L10: mg/L | M10: - | N10: - | O10: - | P10: 48 | Q10: h | R10: QSAR | S10: - | T10: In domain | U10: ECOSAR: DAPHNIA 48 h LC50 Mortality Methacrylates (v1.11) | V10: QSAR Toolbox v.4.8 | W10: Daphnia magna | X10: 48 h | Y10: LC50
B11: B-3 | C11: =VLOOKUP(B11,[1]물질정보!B:C,2,0) -> 97-88-1 | D11: =VLOOKUP(B11,[1]물질정보!B:D,3,0) -> butyl methacrylate | E11: =VLOOKUP(B11,[1]물질정보!B:E,4,0) -> C8H14O2 | F11: =VLOOKUP(B11,[1]물질정보!B:F,5,0) -> 142.2 g/mol | G11: =VLOOKUP(B11,[1]물질정보!B:G,6,0) -> CCCCOC(=O)C(=C)C | H11: 환경 | I11: 물벼룩급성독성 | J11: LC50 | K11: 6.1943902 | L11: mg/L | M11: - | N11: - | O11: - | P11: 48 | Q11: h | R11: QSAR | S11: - | T11: In domain | U11: ECOSAR: DAPHNIA 48 h LC50 Mortality Methacrylates (v1.11) | V11: QSAR Toolbox v.4.8 | W11: Daphnia magna | X11: 48 h | Y11: LC50
B12: B-3 | C12: =VLOOKUP(B12,[1]물질정보!B:C,2,0) -> 97-88-1 | D12: =VLOOKUP(B12,[1]물질정보!B:D,3,0) -> butyl methacrylate | E12: =VLOOKUP(B12,[1]물질정보!B:E,4,0) -> C8H14O2 | F12: =VLOOKUP(B12,[1]물질정보!B:F,5,0) -> 142.2 g/mol | G12: =VLOOKUP(B12,[1]물질정보!B:G,6,0) -> CCCCOC(=O)C(=C)C | H12: 환경 | I12: 물벼룩급성독성 | J12: LC50 | K12: 6.1943902 | L12: mg/L | M12: - | N12: - | O12: - | P12: 48 | Q12: h | R12: QSAR | S12: - | T12: In domain | U12: ECOSAR: DAPHNIA 48 h LC50 Mortality Methacrylates (v1.11) | V12: QSAR Toolbox v.4.8 | W12: Daphnia magna | X12: 48 h | Y12: LC50
B13: B-3 | C13: =VLOOKUP(B13,[1]물질정보!B:C,2,0) -> 97-88-1 | D13: =VLOOKUP(B13,[1]물질정보!B:D,3,0) -> butyl methacrylate | E13: =VLOOKUP(B13,[1]물질정보!B:E,4,0) -> C8H14O2 | F13: =VLOOKUP(B13,[1]물질정보!B:F,5,0) -> 142.2 g/mol | G13: =VLOOKUP(B13,[1]물질정보!B:G,6,0) -> CCCCOC(=O)C(=C)C | H13: 환경 | I13: 어류급성독성 | J13: LC50 | K13: 3.402307 | L13: mg/L | M13: - | N13: - | O13: - | P13: 96 | Q13: h | R13: QSAR | S13: - | T13: In domain | U13: Fathead minnow 96h LC50 - Danish QSAR DB battery model (v1.0) | V13: QSAR Toolbox v.4.8 | W13: Fathead minnow | X13: 96 h | Y13: LC50
B14: B-3 | C14: =VLOOKUP(B14,[1]물질정보!B:C,2,0) -> 97-88-1 | D14: =VLOOKUP(B14,[1]물질정보!B:D,3,0) -> butyl methacrylate | E14: =VLOOKUP(B14,[1]물질정보!B:E,4,0) -> C8H14O2 | F14: =VLOOKUP(B14,[1]물질정보!B:F,5,0) -> 142.2 g/mol | G14: =VLOOKUP(B14,[1]물질정보!B:G,6,0) -> CCCCOC(=O)C(=C)C | H14: 환경 | I14: 어류급성독성 | J14: LC50 | K14: 3.402307 | L14: mg/L | M14: - | N14: - | O14: - | P14: 96 | Q14: h | R14: QSAR | S14: - | T14: In domain | U14: Fathead minnow 96h LC50 - Danish QSAR DB battery model (v1.0) | V14: QSAR Toolbox v.4.8 | W14: Fathead minnow | X14: 96 h | Y14: LC50
B15: B-3 | C15: =VLOOKUP(B15,[1]물질정보!B:C,2,0) -> 97-88-1 | D15: =VLOOKUP(B15,[1]물질정보!B:D,3,0) -> butyl methacrylate | E15: =VLOOKUP(B15,[1]물질정보!B:E,4,0) -> C8H14O2 | F15: =VLOOKUP(B15,[1]물질정보!B:F,5,0) -> 142.2 g/mol | G15: =VLOOKUP(B15,[1]물질정보!B:G,6,0) -> CCCCOC(=O)C(=C)C | H15: 환경 | I15: 어류급성독성 | J15: LC50 | K15: 3.402307 | L15: mg/L | M15: - | N15: - | O15: - | P15: 96 | Q15: h | R15: QSAR | S15: - | T15: In domain | U15: Fathead minnow 96h LC50 - Danish QSAR DB battery model (v1.0) | V15: QSAR Toolbox v.4.8 | W15: Fathead minnow | X15: 96 h | Y15: LC50
B16: B-3 | C16: =VLOOKUP(B16,[1]물질정보!B:C,2,0) -> 97-88-1 | D16: =VLOOKUP(B16,[1]물질정보!B:D,3,0) -> butyl methacrylate | E16: =VLOOKUP(B16,[1]물질정보!B:E,4,0) -> C8H14O2 | F16: =VLOOKUP(B16,[1]물질정보!B:F,5,0) -> 142.2 g/mol | G16: =VLOOKUP(B16,[1]물질정보!B:G,6,0) -> CCCCOC(=O)C(=C)C | H16: 환경 | I16: 어류급성독성 | J16: LC50 | K16: - | L16: log(mmol/L) | M16: - | N16: - | O16: - | P16: 96 | Q16: h | R16: QSAR | S16: - | T16: Not applicable | U16: ECOSAR: FISH (SW) 96 h LC50 Mortality (v1.11) | V16: QSAR Toolbox v.4.8 | W16: Fish (Saltwater) | X16: 96 h | Y16: LC50
B17: B-3 | C17: =VLOOKUP(B17,[1]물질정보!B:C,2,0) -> 97-88-1 | D17: =VLOOKUP(B17,[1]물질정보!B:D,3,0) -> butyl methacrylate | E17: =VLOOKUP(B17,[1]물질정보!B:E,4,0) -> C8H14O2 | F17: =VLOOKUP(B17,[1]물질정보!B:F,5,0) -> 142.2 g/mol | G17: =VLOOKUP(B17,[1]물질정보!B:G,6,0) -> CCCCOC(=O)C(=C)C | H17: 환경 | I17: 어류급성독성 | J17: LC50 | K17: 7.5841459 | L17: mg/L | M17: - | N17: - | O17: - | P17: 96 | Q17: h | R17: QSAR | S17: - | T17: In domain | U17: ECOSAR: FISH 96 h LC50 Mortality Methacrylates (v1.11) | V17: QSAR Toolbox v.4.8 | W17: Fish (Freshwater) | X17: 96 h | Y17: LC50
B18: B-3 | C18: =VLOOKUP(B18,[1]물질정보!B:C,2,0) -> 97-88-1 | D18: =VLOOKUP(B18,[1]물질정보!B:D,3,0) -> butyl methacrylate | E18: =VLOOKUP(B18,[1]물질정보!B:E,4,0) -> C8H14O2 | F18: =VLOOKUP(B18,[1]물질정보!B:F,5,0) -> 142.2 g/mol | G18: =VLOOKUP(B18,[1]물질정보!B:G,6,0) -> CCCCOC(=O)C(=C)C | H18: 환경 | I18: 어류급성독성 | J18: LC50 | K18: 7.5841459 | L18: mg/L | M18: - | N18: - | O18: - | P18: 96 | Q18: h | R18: QSAR | S18: - | T18: In domain | U18: ECOSAR: FISH 96 h LC50 Mortality Methacrylates (v1.11) | V18: QSAR Toolbox v.4.8 | W18: Fish (Freshwater) | X18: 96 h | Y18: LC50
B19: B-3 | C19: =VLOOKUP(B19,[1]물질정보!B:C,2,0) -> 97-88-1 | D19: =VLOOKUP(B19,[1]물질정보!B:D,3,0) -> butyl methacrylate | E19: =VLOOKUP(B19,[1]물질정보!B:E,4,0) -> C8H14O2 | F19: =VLOOKUP(B19,[1]물질정보!B:F,5,0) -> 142.2 g/mol | G19: =VLOOKUP(B19,[1]물질정보!B:G,6,0) -> CCCCOC(=O)C(=C)C | H19: 환경 | I19: 어류급성독성 | J19: LC50 | K19: 7.5841459 | L19: mg/L | M19: - | N19: - | O19: - | P19: 96 | Q19: h | R19: QSAR | S19: - | T19: In domain | U19: ECOSAR: FISH 96 h LC50 Mortality Methacrylates (v1.11) | V19: QSAR Toolbox v.4.8 | W19: Fish (Freshwater) | X19: 96 h | Y19: LC50
B20: B-3 | C20: =VLOOKUP(B20,[1]물질정보!B:C,2,0) -> 97-88-1 | D20: =VLOOKUP(B20,[1]물질정보!B:D,3,0) -> butyl methacrylate | E20: =VLOOKUP(B20,[1]물질정보!B:E,4,0) -> C8H14O2 | F20: =VLOOKUP(B20,[1]물질정보!B:F,5,0) -> 142.2 g/mol | G20: =VLOOKUP(B20,[1]물질정보!B:G,6,0) -> CCCCOC(=O)C(=C)C | H20: 환경 | I20: 담수조류생장저해 | J20: EC50 | K20: 0.14728356 | L20: mg/L | M20: - | N20: - | O20: - | P20: 96 | Q20: h | R20: QSAR | S20: - | T20: In domain | U20: ECOSAR: GREEN ALGAE 96 h EC50 Methacrylates (v1.11) | V20: QSAR Toolbox v.4.8 | W20: Green Algae | X20: 96 h | Y20: EC50
B21: B-3 | C21: =VLOOKUP(B21,[1]물질정보!B:C,2,0) -> 97-88-1 | D21: =VLOOKUP(B21,[1]물질정보!B:D,3,0) -> butyl methacrylate | E21: =VLOOKUP(B21,[1]물질정보!B:E,4,0) -> C8H14O2 | F21: =VLOOKUP(B21,[1]물질정보!B:F,5,0) -> 142.2 g/mol | G21: =VLOOKUP(B21,[1]물질정보!B:G,6,0) -> CCCCOC(=O)C(=C)C | H21: 환경 | I21: 담수조류생장저해 | J21: EC50 | K21: 0.14728356 | L21: mg/L | M21: - | N21: - | O21: - | P21: 96 | Q21: h | R21: QSAR | S21: - | T21: In domain | U21: ECOSAR: GREEN ALGAE 96 h EC50 Methacrylates (v1.11) | V21: QSAR Toolbox v.4.8 | W21: Green Algae | X21: 96 h | Y21: EC50
B22: B-3 | C22: =VLOOKUP(B22,[1]물질정보!B:C,2,0) -> 97-88-1 | D22: =VLOOKUP(B22,[1]물질정보!B:D,3,0) -> butyl methacrylate | E22: =VLOOKUP(B22,[1]물질정보!B:E,4,0) -> C8H14O2 | F22: =VLOOKUP(B22,[1]물질정보!B:F,5,0) -> 142.2 g/mol | G22: =VLOOKUP(B22,[1]물질정보!B:G,6,0) -> CCCCOC(=O)C(=C)C | H22: 환경 | I22: 담수조류생장저해 | J22: EC50 | K22: 0.14728356 | L22: mg/L | M22: - | N22: - | O22: - | P22: 96 | Q22: h | R22: QSAR | S22: - | T22: In domain | U22: ECOSAR: GREEN ALGAE 96 h EC50 Methacrylates (v1.11) | V22: QSAR Toolbox v.4.8 | W22: Green Algae | X22: 96 h | Y22: EC50
B23: B-9 | C23: =VLOOKUP(B23,[1]물질정보!B:C,2,0) -> 2499-95-8 | D23: =VLOOKUP(B23,[1]물질정보!B:D,3,0) -> hexyl acrylate | E23: =VLOOKUP(B23,[1]물질정보!B:E,4,0) -> C9H16O2 | F23: =VLOOKUP(B23,[1]물질정보!B:F,5,0) -> 156.22 g/mol | G23: =VLOOKUP(B23,[1]물질정보!B:G,6,0) -> CCCCCCOC(=O)C=C | H23: 환경 | I23: 담수조류생장저해 | J23: EC50 | K23: 13.81745 | L23: mg/L | M23: - | N23: - | O23: - | P23: 72 | Q23: h | R23: QSAR | S23: - | T23: In domain | U23: Pseudokirchneriella subcapitata 72h EC50 - Danish QSAR DB battery model (v1.0) | V23: QSAR Toolbox v.4.8 | W23: P. subcapitata | X23: 72 h | Y23: EC50
B24: B-9 | C24: =VLOOKUP(B24,[1]물질정보!B:C,2,0) -> 2499-95-8 | D24: =VLOOKUP(B24,[1]물질정보!B:D,3,0) -> hexyl acrylate | E24: =VLOOKUP(B24,[1]물질정보!B:E,4,0) -> C9H16O2 | F24: =VLOOKUP(B24,[1]물질정보!B:F,5,0) -> 156.22 g/mol | G24: =VLOOKUP(B24,[1]물질정보!B:G,6,0) -> CCCCCCOC(=O)C=C | H24: 환경 | I24: 담수조류생장저해 | J24: EC50 | K24: 13.81745 | L24: mg/L | M24: - | N24: - | O24: - | P24: 72 | Q24: h | R24: QSAR | S24: - | T24: In domain | U24: Pseudokirchneriella subcapitata 72h EC50 - Danish QSAR DB battery model (v1.0) | V24: QSAR Toolbox v.4.8 | W24: P. subcapitata | X24: 72 h | Y24: EC50
B25: B-9 | C25: =VLOOKUP(B25,[1]물질정보!B:C,2,0) -> 2499-95-8 | D25: =VLOOKUP(B25,[1]물질정보!B:D,3,0) -> hexyl acrylate | E25: =VLOOKUP(B25,[1]물질정보!B:E,4,0) -> C9H16O2 | F25: =VLOOKUP(B25,[1]물질정보!B:F,5,0) -> 156.22 g/mol | G25: =VLOOKUP(B25,[1]물질정보!B:G,6,0) -> CCCCCCOC(=O)C=C | H25: 환경 | I25: 물벼룩급성독성 | J25: EC50 | K25: 21.8542 | L25: mg/L | M25: - | N25: - | O25: - | P25: 48 | Q25: h | R25: QSAR | S25: - | T25: In domain | U25: Daphnia magna 48h EC50 - Danish QSAR DB battery model (v1.0) | V25: QSAR Toolbox v.4.8 | W25: Daphnia magna | X25: 48 h | Y25: EC50
B26: B-9 | C26: =VLOOKUP(B26,[1]물질정보!B:C,2,0) -> 2499-95-8 | D26: =VLOOKUP(B26,[1]물질정보!B:D,3,0) -> hexyl acrylate | E26: =VLOOKUP(B26,[1]물질정보!B:E,4,0) -> C9H16O2 | F26: =VLOOKUP(B26,[1]물질정보!B:F,5,0) -> 156.22 g/mol | G26: =VLOOKUP(B26,[1]물질정보!B:G,6,0) -> CCCCCCOC(=O)C=C | H26: 환경 | I26: 물벼룩급성독성 | J26: EC50 | K26: 21.8542 | L26: mg/L | M26: - | N26: - | O26: - | P26: 48 | Q26: h | R26: QSAR | S26: - | T26: In domain | U26: Daphnia magna 48h EC50 - Danish QSAR DB battery model (v1.0) | V26: QSAR Toolbox v.4.8 | W26: Daphnia magna | X26: 48 h | Y26: EC50
B27: B-9 | C27: =VLOOKUP(B27,[1]물질정보!B:C,2,0) -> 2499-95-8 | D27: =VLOOKUP(B27,[1]물질정보!B:D,3,0) -> hexyl acrylate | E27: =VLOOKUP(B27,[1]물질정보!B:E,4,0) -> C9H16O2 | F27: =VLOOKUP(B27,[1]물질정보!B:F,5,0) -> 156.22 g/mol | G27: =VLOOKUP(B27,[1]물질정보!B:G,6,0) -> CCCCCCOC(=O)C=C | H27: 환경 | I27: 물벼룩급성독성 | J27: LC50 | K27: 1.554228 | L27: mg/L | M27: - | N27: - | O27: - | P27: 48 | Q27: h | R27: QSAR | S27: - | T27: In domain | U27: ECOSAR: DAPHNIA 48 h LC50 Mortality Acrylates (v1.11) | V27: QSAR Toolbox v.4.8 | W27: Daphnia magna | X27: 48 h | Y27: LC50
B28: B-9 | C28: =VLOOKUP(B28,[1]물질정보!B:C,2,0) -> 2499-95-8 | D28: =VLOOKUP(B28,[1]물질정보!B:D,3,0) -> hexyl acrylate | E28: =VLOOKUP(B28,[1]물질정보!B:E,4,0) -> C9H16O2 | F28: =VLOOKUP(B28,[1]물질정보!B:F,5,0) -> 156.22 g/mol | G28: =VLOOKUP(B28,[1]물질정보!B:G,6,0) -> CCCCCCOC(=O)C=C | H28: 환경 | I28: 물벼룩급성독성 | J28: LC50 | K28: 1.554228 | L28: mg/L | M28: - | N28: - | O28: - | P28: 48 | Q28: h | R28: QSAR | S28: - | T28: In domain | U28: ECOSAR: DAPHNIA 48 h LC50 Mortality Acrylates (v1.11) | V28: QSAR Toolbox v.4.8 | W28: Daphnia magna | X28: 48 h | Y28: LC50
... B50: B-8 | C50: =VLOOKUP(B50,[1]물질정보!B:C,2,0) -> 2478-10-6 | D50: =VLOOKUP(B50,[1]물질정보!B:D,3,0) -> 4-hydroxybutyl acrylate | E50: =VLOOKUP(B50,[1]물질정보!B:E,4,0) -> C7H12O3 | F50: =VLOOKUP(B50,[1]물질정보!B:F,5,0) -> 144.17 g/mol | G50: =VLOOKUP(B50,[1]물질정보!B:G,6,0) -> C=CC(=O)OCCCCO | H50: 환경 | I50: 담수조류생장저해 | J50: EC50 | K50: 1.1479439 | L50: mg/L | M50: - | N50: - | O50: - | P50: 96 | Q50: h | R50: QSAR | S50: - | T50: In domain | U50: ECOSAR: GREEN ALGAE 96 h EC50 Acrylates (v1.11) | V50: QSAR Toolbox v.4.8 | W50: Green Algae | X50: 96 h | Y50: EC50
B51: B-7 | C51: =VLOOKUP(B51,[1]물질정보!B:C,2,0) -> 141-32-2 | D51: =VLOOKUP(B51,[1]물질정보!B:D,3,0) -> butyl acrylate | E51: =VLOOKUP(B51,[1]물질정보!B:E,4,0) -> C7H12O2 | F51: =VLOOKUP(B51,[1]물질정보!B:F,5,0) -> 128.169 g/mol | G51: =VLOOKUP(B51,[1]물질정보!B:G,6,0) -> CCCCOC(=O)C=C | H51: 환경 | I51: 담수조류생장저해 | J51: EC50 | K51: - | L51: mg/L | M51: - | N51: - | O51: - | P51: 72 | Q51: h | R51: QSAR | S51: - | T51: Out of domain | U51: Pseudokirchneriella subcapitata 72h EC50 - Danish QSAR DB battery model (v1.0) | V51: QSAR Toolbox v.4.8 | W51: P. subcapitata | X51: 72 h | Y51: EC50
B52: B-7 | C52: =VLOOKUP(B52,[1]물질정보!B:C,2,0) -> 141-32-2 | D52: =VLOOKUP(B52,[1]물질정보!B:D,3,0) -> butyl acrylate | E52: =VLOOKUP(B52,[1]물질정보!B:E,4,0) -> C7H12O2 | F52: =VLOOKUP(B52,[1]물질정보!B:F,5,0) -> 128.169 g/mol | G52: =VLOOKUP(B52,[1]물질정보!B:G,6,0) -> CCCCOC(=O)C=C | H52: 환경 | I52: 담수조류생장저해 | J52: EC50 | K52: - | L52: mg/L | M52: - | N52: - | O52: - | P52: 72 | Q52: h | R52: QSAR | S52: - | T52: Out of domain | U52: Pseudokirchneriella subcapitata 72h EC50 - Danish QSAR DB battery model (v1.0) | V52: QSAR Toolbox v.4.8 | W52: P. subcapitata | X52: 72 h | Y52: EC50
B53: B-7 | C53: =VLOOKUP(B53,[1]물질정보!B:C,2,0) -> 141-32-2 | D53: =VLOOKUP(B53,[1]물질정보!B:D,3,0) -> butyl acrylate | E53: =VLOOKUP(B53,[1]물질정보!B:E,4,0) -> C7H12O2 | F53: =VLOOKUP(B53,[1]물질정보!B:F,5,0) -> 128.169 g/mol | G53: =VLOOKUP(B53,[1]물질정보!B:G,6,0) -> CCCCOC(=O)C=C | H53: 환경 | I53: 물벼룩급성독성 | J53: EC50 | K53: - | L53: mg/L | M53: - | N53: - | O53: - | P53: 48 | Q53: h | R53: QSAR | S53: - | T53: Out of domain | U53: Daphnia magna 48h EC50 - Danish QSAR DB battery model (v1.0) | V53: QSAR Toolbox v.4.8 | W53: Daphnia magna | X53: 48 h | Y53: EC50
B54: B-7 | C54: =VLOOKUP(B54,[1]물질정보!B:C,2,0) -> 141-32-2 | D54: =VLOOKUP(B54,[1]물질정보!B:D,3,0) -> butyl acrylate | E54: =VLOOKUP(B54,[1]물질정보!B:E,4,0) -> C7H12O2 | F54: =VLOOKUP(B54,[1]물질정보!B:F,5,0) -> 128.169 g/mol | G54: =VLOOKUP(B54,[1]물질정보!B:G,6,0) -> CCCCOC(=O)C=C | H54: 환경 | I54: 물벼룩급성독성 | J54: EC50 | K54: - | L54: mg/L | M54: - | N54: - | O54: - | P54: 48 | Q54: h | R54: QSAR | S54: - | T54: Out of domain | U54: Daphnia magna 48h EC50 - Danish QSAR DB battery model (v1.0) | V54: QSAR Toolbox v.4.8 | W54: Daphnia magna | X54: 48 h | Y54: EC50
B55: B-7 | C55: =VLOOKUP(B55,[1]물질정보!B:C,2,0) -> 141-32-2 | D55: =VLOOKUP(B55,[1]물질정보!B:D,3,0) -> butyl acrylate | E55: =VLOOKUP(B55,[1]물질정보!B:E,4,0) -> C7H12O2 | F55: =VLOOKUP(B55,[1]물질정보!B:F,5,0) -> 128.169 g/mol | G55: =VLOOKUP(B55,[1]물질정보!B:G,6,0) -> CCCCOC(=O)C=C | H55: 환경 | I55: 물벼룩급성독성 | J55: LC50 | K55: 3.0776684 | L55: mg/L | M55: - | N55: - | O55: - | P55: 48 | Q55: h | R55: QSAR | S55: - | T55: In domain | U55: ECOSAR: DAPHNIA 48 h LC50 Mortality Acrylates (v1.11) | V55: QSAR Toolbox v.4.8 | W55: Daphnia magna | X55: 48 h | Y55: LC50
B56: B-7 | C56: =VLOOKUP(B56,[1]물질정보!B:C,2,0) -> 141-32-2 | D56: =VLOOKUP(B56,[1]물질정보!B:D,3,0) -> butyl acrylate | E56: =VLOOKUP(B56,[1]물질정보!B:E,4,0) -> C7H12O2 | F56: =VLOOKUP(B56,[1]물질정보!B:F,5,0) -> 128.169 g/mol | G56: =VLOOKUP(B56,[1]물질정보!B:G,6,0) -> CCCCOC(=O)C=C | H56: 환경 | I56: 물벼룩급성독성 | J56: LC50 | K56: 3.0776684 | L56: mg/L | M56: - | N56: - | O56: - | P56: 48 | Q56: h | R56: QSAR | S56: - | T56: In domain | U56: ECOSAR: DAPHNIA 48 h LC50 Mortality Acrylates (v1.11) | V56: QSAR Toolbox v.4.8 | W56: Daphnia magna | X56: 48 h | Y56: LC50
B57: B-7 | C57: =VLOOKUP(B57,[1]물질정보!B:C,2,0) -> 141-32-2 | D57: =VLOOKUP(B57,[1]물질정보!B:D,3,0) -> butyl acrylate | E57: =VLOOKUP(B57,[1]물질정보!B:E,4,0) -> C7H12O2 | F57: =VLOOKUP(B57,[1]물질정보!B:F,5,0) -> 128.169 g/mol | G57: =VLOOKUP(B57,[1]물질정보!B:G,6,0) -> CCCCOC(=O)C=C | H57: 환경 | I57: 어류급성독성 | J57: LC50 | K57: - | L57: mg/L | M57: - | N57: - | O57: - | P57: 96 | Q57: h | R57: QSAR | S57: - | T57: Out of domain | U57: Fathead minnow 96h LC50 - Danish QSAR DB battery model (v1.0) | V57: QSAR Toolbox v.4.8 | W57: Fathead minnow | X57: 96 h | Y57: LC50
B58: B-7 | C58: =VLOOKUP(B58,[1]물질정보!B:C,2,0) -> 141-32-2 | D58: =VLOOKUP(B58,[1]물질정보!B:D,3,0) -> butyl acrylate | E58: =VLOOKUP(B58,[1]물질정보!B:E,4,0) -> C7H12O2 | F58: =VLOOKUP(B58,[1]물질정보!B:F,5,0) -> 128.169 g/mol | G58: =VLOOKUP(B58,[1]물질정보!B:G,6,0) -> CCCCOC(=O)C=C | H58: 환경 | I58: 어류급성독성 | J58: LC50 | K58: - | L58: mg/L | M58: - | N58: - | O58: - | P58: 96 | Q58: h | R58: QSAR | S58: - | T58: Out of domain | U58: Fathead minnow 96h LC50 - Danish QSAR DB battery model (v1.0) | V58: QSAR Toolbox v.4.8 | W58: Fathead minnow | X58: 96 h | Y58: LC50
B59: B-7 | C59: =VLOOKUP(B59,[1]물질정보!B:C,2,0) -> 141-32-2 | D59: =VLOOKUP(B59,[1]물질정보!B:D,3,0) -> butyl acrylate | E59: =VLOOKUP(B59,[1]물질정보!B:E,4,0) -> C7H12O2 | F59: =VLOOKUP(B59,[1]물질정보!B:F,5,0) -> 128.169 g/mol | G59: =VLOOKUP(B59,[1]물질정보!B:G,6,0) -> CCCCOC(=O)C=C | H59: 환경 | I59: 어류급성독성 | J59: LC50 | K59: 0.88529967 | L59: mg/L | M59: - | N59: - | O59: - | P59: 96 | Q59: h | R59: QSAR | S59: - | T59: In domain | U59: ECOSAR: FISH (SW) 96 h LC50 Mortality Acrylates (v1.11) | V59: QSAR Toolbox v.4.8 | W59: Fish (Saltwater) | X59: 96 h | Y59: LC50
B60: B-7 | C60: =VLOOKUP(B60,[1]물질정보!B:C,2,0) -> 141-32-2 | D60: =VLOOKUP(B60,[1]물질정보!B:D,3,0) -> butyl acrylate | E60: =VLOOKUP(B60,[1]물질정보!B:E,4,0) -> C7H12O2 | F60: =VLOOKUP(B60,[1]물질정보!B:F,5,0) -> 128.169 g/mol | G60: =VLOOKUP(B60,[1]물질정보!B:G,6,0) -> CCCCOC(=O)C=C | H60: 환경 | I60: 어류급성독성 | J60: LC50 | K60: 1.5951973 | L60: mg/L | M60: - | N60: - | O60: - | P60: 96 | Q60: h | R60: QSAR | S60: - | T60: In domain | U60: ECOSAR: FISH 96 h LC50 Mortality Acrylates (v1.11) | V60: QSAR Toolbox v.4.8 | W60: Fish (Freshwater) | X60: 96 h | Y60: LC50
B61: B-7 | C61: =VLOOKUP(B61,[1]물질정보!B:C,2,0) -> 141-32-2 | D61: =VLOOKUP(B61,[1]물질정보!B:D,3,0) -> butyl acrylate | E61: =VLOOKUP(B61,[1]물질정보!B:E,4,0) -> C7H12O2 | F61: =VLOOKUP(B61,[1]물질정보!B:F,5,0) -> 128.169 g/mol | G61: =VLOOKUP(B61,[1]물질정보!B:G,6,0) -> CCCCOC(=O)C=C | H61: 환경 | I61: 어류급성독성 | J61: LC50 | K61: 0.88529967 | L61: mg/L | M61: - | N61: - | O61: - | P61: 96 | Q61: h | R61: QSAR | S61: - | T61: In domain | U61: ECOSAR: FISH (SW) 96 h LC50 Mortality Acrylates (v1.11) | V61: QSAR Toolbox v.4.8 | W61: Fish (Saltwater) | X61: 96 h | Y61: LC50
...
